<robot
  name="x_arm_calib">

  <link
    name="noInertiaBase"/>
  <joint
    name="base_link_to_noInertiaBase"
    type="fixed">
    <origin
      xyz="0 0 0"
      rpy="0 0 0" />
    <parent
      link="noInertiaBase" />
    <child
      link="base_link" />
  </joint>


  <link
    name="base_link">
    <inertial>
      <origin
        xyz="-3.7212E-20 0.075953 -3.7483E-34"
        rpy="0 0 0" />
      <mass
        value="0.11765" />
      <inertia
        ixx="0"
        ixy="0"
        ixz="0"
        iyy="0"
        iyz="0"
        izz="0" />
    </inertial>
    <visual>
      <origin
        xyz="0 0 0"
        rpy="0 0 0" />
      <geometry>
        <mesh
          filename="package://x_arm/meshes/base_link.STL" />
      </geometry>
      <material
        name="">
        <color
          rgba="0.79216 0.81961 0.93333 1" />
      </material>
    </visual>
    <collision>
      <origin
        xyz="0 0 0"
        rpy="0 0 0" />
      <geometry>
        <mesh
          filename="package://x_arm/meshes/base_link.STL" />
      </geometry>
    </collision>
  </link>
  <link
    name="link1">
    <inertial>
      <origin
        xyz="2.5479E-09 3.2756E-09 0.0025605"
        rpy="0 0 0" />
      <mass
        value="0.054247" />
      <inertia
        ixx="0"
        ixy="0"
        ixz="0"
        iyy="0"
        iyz="0"
        izz="0" />
    </inertial>
    <visual>
      <origin
        xyz="0 0 0"
        rpy="0 0 0" />
      <geometry>
        <mesh
          filename="package://x_arm/meshes/link1.STL" />
      </geometry>
      <material
        name="">
        <color
          rgba="0.79216 0.81961 0.93333 1" />
      </material>
    </visual>
    <collision>
      <origin
        xyz="0 0 0"
        rpy="0 0 0" />
      <geometry>
        <mesh
          filename="package://x_arm/meshes/link1.STL" />
      </geometry>
    </collision>
  </link>
  <joint
    name="joint_axis_link1_to_base"
    type="revolute">
    <origin
      xyz="0 0 0"
      rpy="1.5708 1.1818E-16 0" />
    <parent
      link="base_link" />
    <child
      link="link1" />
    <axis
      xyz="0 0 1" />
    <limit
      lower="-0.523"
      upper="2.093"
      effort="1"
      velocity="5" />
  </joint>
  <link
    name="link2">
    <inertial>
      <origin
        xyz="2.6826E-20 -0.12413 -1.3974E-17"
        rpy="0 0 0" />
      <mass
        value="0.45233" />
      <inertia
        ixx="0"
        ixy="0"
        ixz="0"
        iyy="0"
        iyz="0"
        izz="0" />
    </inertial>
    <visual>
      <origin
        xyz="0 0 0"
        rpy="0 0 0" />
      <geometry>
        <mesh
          filename="package://x_arm/meshes/link2.STL" />
      </geometry>
      <material
        name="">
        <color
          rgba="0.79216 0.81961 0.93333 1" />
      </material>
    </visual>
    <collision>
      <origin
        xyz="0 0 0"
        rpy="0 0 0" />
      <geometry>
        <mesh
          filename="package://x_arm/meshes/link2.STL" />
      </geometry>
    </collision>
  </link>
  <joint
    name="joint_axis_link2_to_link1"
    type="revolute">
    <origin
      xyz="0 0 0"
      rpy="1.5708 -1.5708 0" />
    <parent
      link="link1" />
    <child
      link="link2" />
    <axis
      xyz="0 0 1" />
    <limit
      lower="-0.349"
      upper="2.093"
      effort="1"
      velocity="5" />
  </joint>
  <link
    name="link3">
    <inertial>
      <origin
        xyz="1.8042E-19 1.8654E-18 -0.042229"
        rpy="0 0 0" />
      <mass
        value="0.19865" />
      <inertia
        ixx="0"
        ixy="0"
        ixz="0"
        iyy="0"
        iyz="0"
        izz="0" />
    </inertial>
    <visual>
      <origin
        xyz="0 0 0"
        rpy="0 0 0" />
      <geometry>
        <mesh
          filename="package://x_arm/meshes/link3.STL" />
      </geometry>
      <material
        name="">
        <color
          rgba="0.79216 0.81961 0.93333 1" />
      </material>
    </visual>
    <collision>
      <origin
        xyz="0 0 0"
        rpy="0 0 0" />
      <geometry>
        <mesh
          filename="package://x_arm/meshes/link3.STL" />
      </geometry>
    </collision>
  </link>
  <joint
    name="joint_axis_link3_to_link2"
    type="revolute">
    <origin
      xyz="0 -0.205 0"
      rpy="-1.5708 1.5708 0" />
    <parent
      link="link2" />
    <child
      link="link3" />
    <axis
      xyz="0 0 1" />
    <limit
      lower="-1.57"
      upper="1.57"
      effort="1"
      velocity="5" />
  </joint>
  <link
    name="link4">
    <inertial>
      <origin
        xyz="-2.5479E-09 -0.0025605 -3.2756E-09"
        rpy="0 0 0" />
      <mass
        value="0.054247" />
      <inertia
        ixx="0"
        ixy="0"
        ixz="0"
        iyy="0"
        iyz="0"
        izz="0" />
    </inertial>
    <visual>
      <origin
        xyz="0 0 0"
        rpy="0 0 0" />
      <geometry>
        <mesh
          filename="package://x_arm/meshes/link4.STL" />
      </geometry>
      <material
        name="">
        <color
          rgba="0.79216 0.81961 0.93333 1" />
      </material>
    </visual>
    <collision>
      <origin
        xyz="0 0 0"
        rpy="0 0 0" />
      <geometry>
        <mesh
          filename="package://x_arm/meshes/link4.STL" />
      </geometry>
    </collision>
  </link>
  <joint
    name="joint_axis_link4_to_link3"
    type="revolute">
    <origin
      xyz="0 0 -0.1242"
      rpy="-1.5708 6.7516E-18 3.1416" />
    <parent
      link="link3" />
    <child
      link="link4" />
    <axis
      xyz="0 0 1" />
    <limit
      lower="-0.174"
      upper="2.006"
      effort="1"
      velocity="5" />
  </joint>
  <link
    name="link5">
    <inertial>
      <origin
        xyz="-0.0002988 1.525E-08 -0.11718"
        rpy="0 0 0" />
      <mass
        value="0.16504" />
      <inertia
        ixx="0"
        ixy="0"
        ixz="0"
        iyy="0"
        iyz="0"
        izz="0" />
    </inertial>
    <visual>
      <origin
        xyz="0 0 0"
        rpy="0 0 0" />
      <geometry>
        <mesh
          filename="package://x_arm/meshes/link5.STL" />
      </geometry>
      <material
        name="">
        <color
          rgba="0.79216 0.81961 0.93333 1" />
      </material>
    </visual>
    <collision>
      <origin
        xyz="0 0 0"
        rpy="0 0 0" />
      <geometry>
        <mesh
          filename="package://x_arm/meshes/link5.STL" />
      </geometry>
    </collision>
  </link>
  <joint
    name="joint_axis_link5_to_link4"
    type="revolute">
    <origin
      xyz="0 0 0"
      rpy="1.5708 -1.5708 0" />
    <parent
      link="link4" />
    <child
      link="link5" />
    <axis
      xyz="0 0 1" />
    <limit
      lower="-2.093"
      upper="1.919"
      effort="1"
      velocity="5" />
  </joint>





  <link name="calib_link6" />
  <joint
    name="joint_axis_calib_link6_to_link5"
    type="revolute">
    <origin
      xyz="0 0 -0.2555"
      rpy="-1.5708 0 0" />
    <parent
      link="link5" />
    <child
      link="calib_link6" />
    <axis
      xyz="1 0 0" />
    <limit
      lower="-3.14"
      upper="3.14"
      effort="0"
      velocity="0" />
  </joint>


  <link name="calib_link7" />
  <joint
    name="joint_axis_calib_link7_to_calib_link6"
    type="revolute">
    <origin
      xyz="0 0 0"
      rpy="0 0 1.57" />
    <parent
      link="calib_link6" />
    <child
      link="calib_link7" />
    <axis
      xyz="0 0 1" />
    <limit
      lower="-3.14"
      upper="3.14"
      effort="0"
      velocity="0" />
  </joint>
</robot>
